ERROR:tethys.tethys_apps.harvester:App nasaaccess2nasaaccess.log not loaded because of the following error:
Traceback (most recent call last):
  File "/home/riley/tethys/src/tethys_apps/harvester.py", line 221, in _harvest_app_instances
    app_module = __import__(app_module_name, fromlist=[''])
ImportError: No module named 'tethys_apps.tethysapp.nasaaccess2nasaaccess'
ERROR:tethys.tethys_apps.harvester:App nasaaccess2nasaaccess.log not loaded because of the following error:
Traceback (most recent call last):
  File "/home/riley/tethys/src/tethys_apps/harvester.py", line 221, in _harvest_app_instances
    app_module = __import__(app_module_name, fromlist=[''])
ImportError: No module named 'tethys_apps.tethysapp.nasaaccess2nasaaccess'
ERROR:tethys.tethys_apps.harvester:App nasaaccess2nasaaccess.log not loaded because of the following error:
Traceback (most recent call last):
  File "/home/riley/tethys/src/tethys_apps/harvester.py", line 221, in _harvest_app_instances
    app_module = __import__(app_module_name, fromlist=[''])
ImportError: No module named 'tethys_apps.tethysapp.nasaaccess2nasaaccess'
ERROR:tethys.tethys_apps.harvester:App nasaaccess2nasaaccess.log not loaded because of the following error:
Traceback (most recent call last):
  File "/home/riley/tethys/src/tethys_apps/harvester.py", line 221, in _harvest_app_instances
    app_module = __import__(app_module_name, fromlist=[''])
ImportError: No module named 'tethys_apps.tethysapp.nasaaccess2nasaaccess'
ERROR:tethys.tethys_apps.harvester:App nasaaccess2nasaaccess.log not loaded because of the following error:
Traceback (most recent call last):
  File "/home/riley/tethys/src/tethys_apps/harvester.py", line 221, in _harvest_app_instances
    app_module = __import__(app_module_name, fromlist=[''])
ImportError: No module named 'tethys_apps.tethysapp.nasaaccess2nasaaccess'
ERROR:tethys.tethys_apps.harvester:App nasaaccess2nasaaccess.log not loaded because of the following error:
Traceback (most recent call last):
  File "/home/riley/tethys/src/tethys_apps/harvester.py", line 221, in _harvest_app_instances
    app_module = __import__(app_module_name, fromlist=[''])
ImportError: No module named 'tethys_apps.tethysapp.nasaaccess2nasaaccess'
ERROR:tethys.tethys_apps.harvester:App nasaaccess2nasaaccess.log not loaded because of the following error:
Traceback (most recent call last):
  File "/home/riley/tethys/src/tethys_apps/harvester.py", line 221, in _harvest_app_instances
    app_module = __import__(app_module_name, fromlist=[''])
ImportError: No module named 'tethys_apps.tethysapp.nasaaccess2nasaaccess'
ERROR:tethys.tethys_apps.harvester:App nasaaccess2nasaaccess.log not loaded because of the following error:
Traceback (most recent call last):
  File "/home/riley/tethys/src/tethys_apps/harvester.py", line 221, in _harvest_app_instances
    app_module = __import__(app_module_name, fromlist=[''])
ImportError: No module named 'tethys_apps.tethysapp.nasaaccess2nasaaccess'
ERROR:tethys.tethys_apps.harvester:App nasaaccess2nasaaccess.log not loaded because of the following error:
Traceback (most recent call last):
  File "/home/riley/tethys/src/tethys_apps/harvester.py", line 221, in _harvest_app_instances
    app_module = __import__(app_module_name, fromlist=[''])
ImportError: No module named 'tethys_apps.tethysapp.nasaaccess2nasaaccess'
ERROR:tethys.tethys_apps.harvester:App nasaaccess2nasaaccess.log not loaded because of the following error:
Traceback (most recent call last):
  File "/home/riley/tethys/src/tethys_apps/harvester.py", line 221, in _harvest_app_instances
    app_module = __import__(app_module_name, fromlist=[''])
ImportError: No module named 'tethys_apps.tethysapp.nasaaccess2nasaaccess'
ERROR:tethys.tethys_apps.harvester:App nasaaccess2nasaaccess.log not loaded because of the following error:
Traceback (most recent call last):
  File "/home/riley/tethys/src/tethys_apps/harvester.py", line 221, in _harvest_app_instances
    app_module = __import__(app_module_name, fromlist=[''])
ImportError: No module named 'tethys_apps.tethysapp.nasaaccess2nasaaccess'
ERROR:tethys.tethys_apps.harvester:App nasaaccess2nasaaccess.log not loaded because of the following error:
Traceback (most recent call last):
  File "/home/riley/tethys/src/tethys_apps/harvester.py", line 221, in _harvest_app_instances
    app_module = __import__(app_module_name, fromlist=[''])
ImportError: No module named 'tethys_apps.tethysapp.nasaaccess2nasaaccess'
ERROR:tethys.tethys_apps.harvester:App nasaaccess2nasaaccess.log not loaded because of the following error:
Traceback (most recent call last):
  File "/home/riley/tethys/src/tethys_apps/harvester.py", line 221, in _harvest_app_instances
    app_module = __import__(app_module_name, fromlist=[''])
ImportError: No module named 'tethys_apps.tethysapp.nasaaccess2nasaaccess'
ERROR:django.request:Internal Server Error: /apps/nasaaccess2/
Traceback (most recent call last):
  File "/home/riley/tethys/miniconda/envs/tethys/lib/python3.5/site-packages/django/core/handlers/exception.py", line 41, in inner
    response = get_response(request)
  File "/home/riley/tethys/miniconda/envs/tethys/lib/python3.5/site-packages/django/core/handlers/base.py", line 249, in _legacy_get_response
    response = self._get_response(request)
  File "/home/riley/tethys/miniconda/envs/tethys/lib/python3.5/site-packages/django/core/handlers/base.py", line 187, in _get_response
    response = self.process_exception_by_middleware(e, request)
  File "/home/riley/tethys/miniconda/envs/tethys/lib/python3.5/site-packages/django/core/handlers/base.py", line 185, in _get_response
    response = wrapped_callback(request, *callback_args, **callback_kwargs)
  File "/home/riley/tethys/src/tethys_apps/tethysapp/nasaaccess2/controllers.py", line 18, in home
    shp_files_sys = os.listdir(shapefile_path)
FileNotFoundError: [Errno 2] No such file or directory: '/home/riley/tethys/src/tethys_apps/tethysapp/nasaaccess2/shapefiles'
ERROR:django.server:"GET /apps/nasaaccess2/ HTTP/1.1" 500 85650
WARNING:django.request:Not Found: /favicon.ico
WARNING:django.server:"GET /favicon.ico HTTP/1.1" 404 3621
ERROR:tethys.tethys_apps.harvester:App nasaaccess2nasaaccess.log not loaded because of the following error:
Traceback (most recent call last):
  File "/home/riley/tethys/src/tethys_apps/harvester.py", line 221, in _harvest_app_instances
    app_module = __import__(app_module_name, fromlist=[''])
ImportError: No module named 'tethys_apps.tethysapp.nasaaccess2nasaaccess'
ERROR:tethys.tethys_apps.harvester:App nasaaccess2nasaaccess.log not loaded because of the following error:
Traceback (most recent call last):
  File "/home/riley/tethys/src/tethys_apps/harvester.py", line 221, in _harvest_app_instances
    app_module = __import__(app_module_name, fromlist=[''])
ImportError: No module named 'tethys_apps.tethysapp.nasaaccess2nasaaccess'
